import os
import time
import traceback
from celery import Celery
from app.bd_helper.bd_types import Checks
from os.path import join, exists
from bson import ObjectId

from app.bd_helper.bd_helper import *
from app.main.api_checker import check
from app.main.parser import parse

import os
from logging import getLogger
logger = getLogger('root')

celery = Celery(__name__)
celery.conf.broker_url = os.environ.get("CELERY_BROKER_URL", "redis://localhost:6379")
celery.conf.result_backend = os.environ.get("CELERY_RESULT_BACKEND", "redis://localhost:6379")

@celery.task(name="create_task")
def create_task(filename, converted_id, username=''):
    try:
        presentation_name = basename(filename)

        checks = Checks({
            'conv_pdf_fs_id': ObjectId(converted_id),
            'user': username
        })

        check(parse(filename), checks, presentation_name)
        checks_id = add_api_check(checks, filename)

        os.remove(filename)

        return {'check_id': str(checks_id), 'score': checks.score}
    except Exception as e:
        logger.error("\tПри обработке произошла ошибка: " + str(e), exc_info=True)
        return 'Not OK, error: {}'.format(traceback.format_exc())
